Workbook

Sheet Summary
A1: Computyme rules to deal with
A2: Every business rule in the 367 BP_Computyme programs, with source lines and a suggested tag. Work through the Rules tab: fill the yellow columns (Decision, Owner, PIV2 home, Notes).
A3: Example: IV.AUTO.ORDER.03 · Decision SIMPLIFY · Owner Mark · PIV2 home "Product page › Order (PO build)" · Notes "suggest by vendor, one PO per vendor".
A5: Domain | B5: Programs | C5: Rules | D5: KEEP | E5: SIMPLIFY | F5: QUESTION | G5: OBSOLETE | H5: OBSOLETE-INTEGRATION | I5: WAREHOUSE-ONLY | J5: Decided | K5: Open
A6: Vendors | B6: =COUNTIF(Programs!$B$2:$B$368,A6) -> 10 | C6: =COUNTIF(Rules!$C$2:$C$1568,A6) -> 26 | D6: =COUNTIFS(Rules!$C$2:$C$1568,$A6,Rules!$H$2:$H$1568,"KEEP") -> 10 | E6: =COUNTIFS(Rules!$C$2:$C$1568,$A6,Rules!$H$2:$H$1568,"SIMPLIFY") -> 4 | F6: =COUNTIFS(Rules!$C$2:$C$1568,$A6,Rules!$H$2:$H$1568,"QUESTION") -> 10 | G6: =COUNTIFS(Rules!$C$2:$C$1568,$A6,Rules!$H$2:$H$1568,"OBSOLETE") -> 2 | H6: =COUNTIFS(Rules!$C$2:$C$1568,$A6,Rules!$H$2:$H$1568,"OBSOLETE-INTEGRATION") -> 0 | I6: =COUNTIFS(Rules!$C$2:$C$1568,$A6,Rules!$H$2:$H$1568,"WAREHOUSE-ONLY") -> 0 | J6: =COUNTIFS(Rules!$C$2:$C$1568,A6,Rules!$I$2:$I$1568,"<>") -> 0 | K6: =C6-J6 -> 26
A7: AP | B7: =COUNTIF(Programs!$B$2:$B$368,A7) -> 10 | C7: =COUNTIF(Rules!$C$2:$C$1568,A7) -> 38 | D7: =COUNTIFS(Rules!$C$2:$C$1568,$A7,Rules!$H$2:$H$1568,"KEEP") -> 20 | E7: =COUNTIFS(Rules!$C$2:$C$1568,$A7,Rules!$H$2:$H$1568,"SIMPLIFY") -> 4 | F7: =COUNTIFS(Rules!$C$2:$C$1568,$A7,Rules!$H$2:$H$1568,"QUESTION") -> 8 | G7: =COUNTIFS(Rules!$C$2:$C$1568,$A7,Rules!$H$2:$H$1568,"OBSOLETE") -> 3 | H7: =COUNTIFS(Rules!$C$2:$C$1568,$A7,Rules!$H$2:$H$1568,"OBSOLETE-INTEGRATION") -> 3 | I7: =COUNTIFS(Rules!$C$2:$C$1568,$A7,Rules!$H$2:$H$1568,"WAREHOUSE-ONLY") -> 0 | J7: =COUNTIFS(Rules!$C$2:$C$1568,A7,Rules!$I$2:$I$1568,"<>") -> 0 | K7: =C7-J7 -> 38
A8: Products | B8: =COUNTIF(Programs!$B$2:$B$368,A8) -> 39 | C8: =COUNTIF(Rules!$C$2:$C$1568,A8) -> 129 | D8: =COUNTIFS(Rules!$C$2:$C$1568,$A8,Rules!$H$2:$H$1568,"KEEP") -> 63 | E8: =COUNTIFS(Rules!$C$2:$C$1568,$A8,Rules!$H$2:$H$1568,"SIMPLIFY") -> 9 | F8: =COUNTIFS(Rules!$C$2:$C$1568,$A8,Rules!$H$2:$H$1568,"QUESTION") -> 42 | G8: =COUNTIFS(Rules!$C$2:$C$1568,$A8,Rules!$H$2:$H$1568,"OBSOLETE") -> 10 | H8: =COUNTIFS(Rules!$C$2:$C$1568,$A8,Rules!$H$2:$H$1568,"OBSOLETE-INTEGRATION") -> 4 | I8: =COUNTIFS(Rules!$C$2:$C$1568,$A8,Rules!$H$2:$H$1568,"WAREHOUSE-ONLY") -> 1 | J8: =COUNTIFS(Rules!$C$2:$C$1568,A8,Rules!$I$2:$I$1568,"<>") -> 0 | K8: =C8-J8 -> 129
A9: Inventory | B9: =COUNTIF(Programs!$B$2:$B$368,A9) -> 37 | C9: =COUNTIF(Rules!$C$2:$C$1568,A9) -> 192 | D9: =COUNTIFS(Rules!$C$2:$C$1568,$A9,Rules!$H$2:$H$1568,"KEEP") -> 80 | E9: =COUNTIFS(Rules!$C$2:$C$1568,$A9,Rules!$H$2:$H$1568,"SIMPLIFY") -> 12 | F9: =COUNTIFS(Rules!$C$2:$C$1568,$A9,Rules!$H$2:$H$1568,"QUESTION") -> 62 | G9: =COUNTIFS(Rules!$C$2:$C$1568,$A9,Rules!$H$2:$H$1568,"OBSOLETE") -> 22 | H9: =COUNTIFS(Rules!$C$2:$C$1568,$A9,Rules!$H$2:$H$1568,"OBSOLETE-INTEGRATION") -> 0 | I9: =COUNTIFS(Rules!$C$2:$C$1568,$A9,Rules!$H$2:$H$1568,"WAREHOUSE-ONLY") -> 16 | J9: =COUNTIFS(Rules!$C$2:$C$1568,A9,Rules!$I$2:$I$1568,"<>") -> 0 | K9: =C9-J9 -> 192
A10: Orders | B10: =COUNTIF(Programs!$B$2:$B$368,A10) -> 59 | C10: =COUNTIF(Rules!$C$2:$C$1568,A10) -> 375 | D10: =COUNTIFS(Rules!$C$2:$C$1568,$A10,Rules!$H$2:$H$1568,"KEEP") -> 136 | E10: =COUNTIFS(Rules!$C$2:$C$1568,$A10,Rules!$H$2:$H$1568,"SIMPLIFY") -> 18 | F10: =COUNTIFS(Rules!$C$2:$C$1568,$A10,Rules!$H$2:$H$1568,"QUESTION") -> 147 | G10: =COUNTIFS(Rules!$C$2:$C$1568,$A10,Rules!$H$2:$H$1568,"OBSOLETE") -> 34 | H10: =COUNTIFS(Rules!$C$2:$C$1568,$A10,Rules!$H$2:$H$1568,"OBSOLETE-INTEGRATION") -> 18 | I10: =COUNTIFS(Rules!$C$2:$C$1568,$A10,Rules!$H$2:$H$1568,"WAREHOUSE-ONLY") -> 22 | J10: =COUNTIFS(Rules!$C$2:$C$1568,A10,Rules!$I$2:$I$1568,"<>") -> 0 | K10: =C10-J10 -> 375
A11: EDI | B11: =COUNTIF(Programs!$B$2:$B$368,A11) -> 9 | C11: =COUNTIF(Rules!$C$2:$C$1568,A11) -> 109 | D11: =COUNTIFS(Rules!$C$2:$C$1568,$A11,Rules!$H$2:$H$1568,"KEEP") -> 37 | E11: =COUNTIFS(Rules!$C$2:$C$1568,$A11,Rules!$H$2:$H$1568,"SIMPLIFY") -> 8 | F11: =COUNTIFS(Rules!$C$2:$C$1568,$A11,Rules!$H$2:$H$1568,"QUESTION") -> 54 | G11: =COUNTIFS(Rules!$C$2:$C$1568,$A11,Rules!$H$2:$H$1568,"OBSOLETE") -> 2 | H11: =COUNTIFS(Rules!$C$2:$C$1568,$A11,Rules!$H$2:$H$1568,"OBSOLETE-INTEGRATION") -> 8 | I11: =COUNTIFS(Rules!$C$2:$C$1568,$A11,Rules!$H$2:$H$1568,"WAREHOUSE-ONLY") -> 0 | J11: =COUNTIFS(Rules!$C$2:$C$1568,A11,Rules!$I$2:$I$1568,"<>") -> 0 | K11: =C11-J11 -> 109
A12: Members | B12: =COUNTIF(Programs!$B$2:$B$368,A12) -> 50 | C12: =COUNTIF(Rules!$C$2:$C$1568,A12) -> 180 | D12: =COUNTIFS(Rules!$C$2:$C$1568,$A12,Rules!$H$2:$H$1568,"KEEP") -> 72 | E12: =COUNTIFS(Rules!$C$2:$C$1568,$A12,Rules!$H$2:$H$1568,"SIMPLIFY") -> 9 | F12: =COUNTIFS(Rules!$C$2:$C$1568,$A12,Rules!$H$2:$H$1568,"QUESTION") -> 85 | G12: =COUNTIFS(Rules!$C$2:$C$1568,$A12,Rules!$H$2:$H$1568,"OBSOLETE") -> 12 | H12: =COUNTIFS(Rules!$C$2:$C$1568,$A12,Rules!$H$2:$H$1568,"OBSOLETE-INTEGRATION") -> 2 | I12: =COUNTIFS(Rules!$C$2:$C$1568,$A12,Rules!$H$2:$H$1568,"WAREHOUSE-ONLY") -> 0 | J12: =COUNTIFS(Rules!$C$2:$C$1568,A12,Rules!$I$2:$I$1568,"<>") -> 0 | K12: =C12-J12 -> 180
A13: AR | B13: =COUNTIF(Programs!$B$2:$B$368,A13) -> 77 | C13: =COUNTIF(Rules!$C$2:$C$1568,A13) -> 337 | D13: =COUNTIFS(Rules!$C$2:$C$1568,$A13,Rules!$H$2:$H$1568,"KEEP") -> 145 | E13: =COUNTIFS(Rules!$C$2:$C$1568,$A13,Rules!$H$2:$H$1568,"SIMPLIFY") -> 20 | F13: =COUNTIFS(Rules!$C$2:$C$1568,$A13,Rules!$H$2:$H$1568,"QUESTION") -> 114 | G13: =COUNTIFS(Rules!$C$2:$C$1568,$A13,Rules!$H$2:$H$1568,"OBSOLETE") -> 39 | H13: =COUNTIFS(Rules!$C$2:$C$1568,$A13,Rules!$H$2:$H$1568,"OBSOLETE-INTEGRATION") -> 18 | I13: =COUNTIFS(Rules!$C$2:$C$1568,$A13,Rules!$H$2:$H$1568,"WAREHOUSE-ONLY") -> 1 | J13: =COUNTIFS(Rules!$C$2:$C$1568,A13,Rules!$I$2:$I$1568,"<>") -> 0 | K13: =C13-J13 -> 337
A14: Reporting | B14: =COUNTIF(Programs!$B$2:$B$368,A14) -> 24 | C14: =COUNTIF(Rules!$C$2:$C$1568,A14) -> 123 | D14: =COUNTIFS(Rules!$C$2:$C$1568,$A14,Rules!$H$2:$H$1568,"KEEP") -> 11 | E14: =COUNTIFS(Rules!$C$2:$C$1568,$A14,Rules!$H$2:$H$1568,"SIMPLIFY") -> 10 | F14: =COUNTIFS(Rules!$C$2:$C$1568,$A14,Rules!$H$2:$H$1568,"QUESTION") -> 90 | G14: =COUNTIFS(Rules!$C$2:$C$1568,$A14,Rules!$H$2:$H$1568,"OBSOLETE") -> 11 | H14: =COUNTIFS(Rules!$C$2:$C$1568,$A14,Rules!$H$2:$H$1568,"OBSOLETE-INTEGRATION") -> 1 | I14: =COUNTIFS(Rules!$C$2:$C$1568,$A14,Rules!$H$2:$H$1568,"WAREHOUSE-ONLY") -> 0 | J14: =COUNTIFS(Rules!$C$2:$C$1568,A14,Rules!$I$2:$I$1568,"<>") -> 0 | K14: =C14-J14 -> 123
A15: Utility | B15: =COUNTIF(Programs!$B$2:$B$368,A15) -> 52 | C15: =COUNTIF(Rules!$C$2:$C$1568,A15) -> 58 | D15: =COUNTIFS(Rules!$C$2:$C$1568,$A15,Rules!$H$2:$H$1568,"KEEP") -> 5 | E15: =COUNTIFS(Rules!$C$2:$C$1568,$A15,Rules!$H$2:$H$1568,"SIMPLIFY") -> 5 | F15: =COUNTIFS(Rules!$C$2:$C$1568,$A15,Rules!$H$2:$H$1568,"QUESTION") -> 2 | G15: =COUNTIFS(Rules!$C$2:$C$1568,$A15,Rules!$H$2:$H$1568,"OBSOLETE") -> 43 | H15: =COUNTIFS(Rules!$C$2:$C$1568,$A15,Rules!$H$2:$H$1568,"OBSOLETE-INTEGRATION") -> 2 | I15: =COUNTIFS(Rules!$C$2:$C$1568,$A15,Rules!$H$2:$H$1568,"WAREHOUSE-ONLY") -> 1 | J15: =COUNTIFS(Rules!$C$2:$C$1568,A15,Rules!$I$2:$I$1568,"<>") -> 0 | K15: =C15-J15 -> 58
A16: Total | B16: =SUM(B6:B15) -> 367 | C16: =SUM(C6:C15) -> 1567 | D16: =SUM(D6:D15) -> 579 | E16: =SUM(E6:E15) -> 99 | F16: =SUM(F6:F15) -> 614 | G16: =SUM(G6:G15) -> 178 | H16: =SUM(H6:H15) -> 56 | I16: =SUM(I6:I15) -> 41 | ... K16: =SUM(K6:K15) -> 1567
A18: Relevance (programs)
A19: VENDOR | B19: =COUNTIF(Programs!$E$2:$E$368,"*VENDOR*") -> 82
A20: PRODUCT | B20: =COUNTIF(Programs!$E$2:$E$368,"*PRODUCT*") -> 129
A21: PO | B21: =COUNTIF(Programs!$E$2:$E$368,"*PO*") -> 63
A22: PRICING | B22: =COUNTIF(Programs!$E$2:$E$368,"*PRICING*") -> 89
A24: Tags: KEEP rebuild as is · SIMPLIFY right intent, cleaner build · QUESTION business must answer (every hard-coded member/vendor/product number) · OBSOLETE dead/retired (COO/CFO sign-off) · OBSOLETE-INTEGRATION legacy file format (CTO sign-off) · WAREHOUSE-ONLY stays with warehouse system. Source: github PhotographicResearchOrg/Extracted-rules, BP/.

Sheet Rules
A1: Rule ID | B1: Program | C1: Domain | D1: Mode | E1: Relevance | F1: Rule | G1: Source lines | H1: Suggested tag | I1: Decision | J1: Owner | K1: PIV2 home | L1: Notes
A2: AR17.01 | B2: AR17 | C2: Vendors | D2: Utility/maintenance | E2: VENDOR | F2: Hard-coded vendors 195 and 279: IVEND attr 4 (F4) = sum of AMOUNT (attr 2) and attr 5 (F5) = sum of SURCHG (attr 3) for those two vendors | G2: L1, L16-24 | H2: QUESTION
A3: IV2.01 | B3: IV2 | C3: Vendors | D3: Interactive | E3: VENDOR, PRICING | F3: New vendor number from CONTROL 'VEND' attr 1; counter incremented by 3 after each add | G3: L32, L177 | H3: QUESTION
A4: IV2.02 | B4: IV2 | C4: Vendors | D4: Interactive | E4: VENDOR, PRICING | F4: Hard-coded skipped vendor numbers 272, 713, 839, 902, 965 (if next number is one of these add 3) | G4: L12, L33 | H4: QUESTION
A5: IV2.03 | B5: IV2 | C5: Vendors | D5: Interactive | E5: VENDOR, PRICING | F5: A new vendor must first exist in APMST; name, address, city/state, zip, phone are copied from APMST attrs 1,3,4,5,6,7 | G5: L65-69 | H5: KEEP
A6: IV2.04 | B6: IV2 | C6: Vendors | D6: Interactive | E6: VENDOR, PRICING | F6: One APMST vendor may link to only one PRO vendor: VNIDX holds two-way index (vendor→APID and APID→vendor); duplicate rejected | G6: L70-71, L175-176 | H6: KEEP
A7: IV2.05 | B7: IV2 | C7: Vendors | D7: Interactive | E7: VENDOR, PRICING | F7: VNMST attr 12 APID = linked AP vendor | G7: L172 | H7: KEEP
A8: IV2.06 | B8: IV2 | C8: Vendors | D8: Interactive | E8: VENDOR, PRICING | F8: Validations: name 1-25 chars, name2 ≤25, street 1-25, city/state 1-22, zip exactly 5 digits, phone NNN-NNN-NNNN | G8: L76-124 | H8: SIMPLIFY
A9: IV2.07 | B9: IV2 | C9: Vendors | D9: Interactive | E9: VENDOR, PRICING | F9: Surcharge percent attr 8 stored in tenths of a percent (verify shows NI/10) | G9: L127-137 | H9: KEEP
A10: IV2.08 | B10: IV2 | C10: Vendors | D10: Interactive | E10: VENDOR, PRICING | F10: Surcharge type attr 6 (CODE), required when surcharge ≠ 0: 1 = surcharge rebated by vendor, 2 = surcharge added to vendor invoice | G10: L139-151 | H10: KEEP
A11: IV2.09 | B11: IV2 | C11: Vendors | D11: Interactive | E11: VENDOR, PRICING | F11: Vendor billing guarantee attr 13: 0 = none, 1 = vendor guarantees member billing | G11: L153-165 | H11: QUESTION
A12: IV46.9999.01 | B12: IV46.9999 | C12: Vendors | D12: Subroutine | E12: VENDOR, PO | F12: Misc vendor fields (name first; layout and validations defined in PROMPTS record, not in code) packed into INFO and stored on the PO | G12: L26-28, L55-63 | H12: QUESTION
A13: IV9.01 | B13: IV9 | C13: Vendors | D13: Report/print | E13: VENDOR | F13: Label = VNMST attr 1 NAME, 2 NAME2, 3 STREET, 4 CITY.STATE + 5 ZIP; quantity must be a multiple of 3; max 40 vendors | G13: L12-33 | H13: OBSOLETE
... A61: CUSTRBTNEW1.02 | B61: CUSTRBTNEW1 | C61: AP | D61: Test-variant | E61: PRODUCT | F61: No check-exists test: MATWRITE overwrites any existing RBTDATA record with the same number; no void path | G61: L74 | H61: QUESTION
A62: FIX.RBTCHK.01 | B62: FIX.RBTCHK | C62: AP | D62: Utility/maintenance | F62: Hard-coded: checks >= 35790 copied to new id '2' + chars 2-5 of old id (old record not deleted) | G62: L4-8 | H62: OBSOLETE
A63: LJ.CHK.TEST.01 | B63: LJ.CHK.TEST | C63: AP | D63: Test-variant | F63: Printer-test only; prints dummy payee/amount and MICR string 'C12345C A028000121A 261D050346C' (contains what looks like a routing/account number — confirm whether real) | G63: L16 | H63: OBSOLETE
A64: REBUILD.APBR.01 | B64: REBUILD.APBR | C64: AP | D64: Utility/maintenance | E64: VENDOR | F64: APDIST key ID[1,4] = AP vendor (APMST key); APBR record per check # (APDIST attr 15): attr 1 vendor, 2 vendor name (APMST attr 1), 3 date paid (APDIST attr 10), 4 sum gross (attr 3), 5 sum discount (attr 4), 6 net = gross - discount | G64: L8-19 | H64: KEEP
A65: REBUILD.APBR.02 | B65: REBUILD.APBR | C65: AP | D65: Utility/maintenance | E65: VENDOR | F65: Hard-coded saved list APDIST.JOHN (user-specific one-off) | G65: L5 | H65: OBSOLETE
A66: ADJ.ARHIST.01 | B66: ADJ.ARHIST | C66: Products | D66: Utility/maintenance | E66: PRODUCT, PRICING | F66: Average cost = INT(SUM(IVMST attr 25 AMT.RECD) / SUM(IVMST attr 24 QTY.REC)) when total received qty > 0 | G66: L13-14 | H66: QUESTION
A67: ADJ.ARHIST.02 | B67: ADJ.ARHIST | C67: Products | D67: Utility/maintenance | E67: PRODUCT, PRICING | F67: Fallback when nothing received: use IVMST attr 19 RAW cost; if RAW ends in "Y", cost = INT(numeric part / 110), else RAW as-is (the /110 implies "Y" means a 10% loaded price and a cents→dollars shift; units inconsistent with the other branch) | G67: L15-16 | H67: QUESTION
A68: ADJ.ARHIST.03 | B68: ADJ.ARHIST | C68: Products | D68: Utility/maintenance | E68: PRODUCT, PRICING | F68: ARHIST attr 15 (COST per ARSHIP naming) for each line = line qty (attr 3) × average cost | G68: L19 | H68: OBSOLETE
A69: BLD.IVMST.PW.01 | B69: BLD.IVMST.PW | C69: Products | D69: Outbound-generator | E69: PRODUCT, PRICING | F69: Only products with IVMST attr 36 DISPLAY ≠ "N" are exported (06-09-08) | G69: L6, L20 | H69: KEEP
A70: BLD.IVMST.PW.02 | B70: BLD.IVMST.PW | C70: Products | D70: Outbound-generator | E70: PRODUCT, PRICING | F70: Member price = ROUND(NET.1 (attr 8, cents) × (1000 + SCH.PCT) / 1000), i.e. surcharge percentage stored in tenths of a percent (SCH.PCT via include; IVMST dict attr 12 = PCT) | G70: L28-29 | H70: KEEP
A71: BLD.IVMST.PW.03 | B71: BLD.IVMST.PW | C71: Products | D71: Outbound-generator | E71: PRODUCT, PRICING | F71: Price exported in cents (MD2 conversion commented out); description tabs replaced by spaces | G71: L26, L30 | H71: QUESTION
A72: BLD.IVMST.PW.04 | B72: BLD.IVMST.PW | C72: Products | D72: Outbound-generator | E72: PRODUCT, PRICING | F72: Tab-delimited file staged as a PWDB record (07-02-08 replaced XML) | G72: L5, L18, L31-41 | H72: OBSOLETE-INTEGRATION
A73: BLD.IVMST.XML.01 | B73: BLD.IVMST.XML | C73: Products | D73: Outbound-generator | E73: PRODUCT, PRICING | F73: Same selection (DISPLAY ≠ "N") and price formula ROUND(NET.1 × (1000 + SCH.PCT)/1000) as BLD.IVMST.PW, but price output in dollars (MD2) | G73: L22, L29-31 | H73: KEEP
A74: BLD.IVMST.XML.02 | B74: BLD.IVMST.XML | C74: Products | D74: Outbound-generator | E74: PRODUCT, PRICING | F74: XML layout (INVENTORY/DETAIL with Product, Description CDATA, Cost, optional Multiple/Status/UPC) staged in PWDB | G74: L20, L32-43 | H74: OBSOLETE-INTEGRATION
A75: BUILD.IVCAT.01 | B75: BUILD.IVCAT | C75: Products | D75: Utility/maintenance | E75: PRODUCT | F75: Hard-coded UPC prefix "0291440" + PRO product number + UPC-A check digit (odd positions ×3 + even, check = round-up-to-10 − total) | G75: L11-21 | H75: QUESTION
... A360: IVPO.ON.ORD.01 | B360: IVPO.ON.ORD | C360: Inventory | D360: Subroutine | E360: PO | F360: For each value I: on-order = QO<1,I> − SUM(QR<1,I>) (ordered minus all received sub-values) | G360: L2-5 | H360: KEEP
A361: I_BLD.MEQHIST.01 | B361: I_BLD.MEQHIST | C361: Inventory | D361: Subroutine | F361: MEQHIST entries whose key date (first '*' field, internal date) is older than TODAY-30 are deleted (30-day retention) | G361: L5-16 | H361: WAREHOUSE-ONLY
A362: I_BLD.MEQHIST.02 | B362: I_BLD.MEQHIST | C362: Inventory | D362: Subroutine | F362: Header record MEQDATA 'RECS' (default '0,0') holds the record count in its 2nd comma field; it is copied to MEQHIST key TODAY*TIME*RECS, then each MEQDATA record 1..RECS is copied to MEQHIST key TODAY*TIME*n | G362: L17-31 | H362: WAREHOUSE-ONLY
A363: I_IV46_COMMON.01 | B363: I_IV46_COMMON | C363: Inventory | D363: Subroutine | E363: PO | F363: PO header context carried in COMMON: PO number, PO date, primary vendor number+name and second vendor number+name (SVND purpose not stated here) | G363: L2 | H363: QUESTION
A364: I_IV46_COMMON.02 | B364: I_IV46_COMMON | C364: Inventory | D364: Subroutine | E364: PO | F364: Fixed file-handle slot map (FILES(1..23): PROMPTS, SCREENS, APMST, ARMST, CONTROL, CUSTIDX, IVCAT, IVCUST, IVEMP, IVINV, IVSOLD, IVMST, THROWAYS, ZIPPREF, TERMINALS, APIDX, TREES, IVORD, IVPO, IVNEW, IVSPORD) | G364: L7-29 | H364: OBSOLETE
A365: I_MEQ.ERROR.01 | B365: I_MEQ.ERROR | C365: Inventory | D365: Report/print | E365: PRODUCT | F365: Error report lists Emp, Store, Seq, Product, Qty, message and the prior record's product + description (IVINV attr 6 description, else IVMST attr 3 — attr 3 per D_IVMST is REQ, so "attr 3 (purpose unclear)" used as description) | G365: L13-38 | H365: WAREHOUSE-ONLY
A366: I_MEQ.ERROR.02 | B366: I_MEQ.ERROR | C366: Inventory | D366: Report/print | E366: PRODUCT | F366: Catalog-number resolution fallback: look up IVCAT with full product; if length < 10 use as is; else try substrings [2,10], [2,12], [1,10], [1,11]; else use raw value | G366: L69-82 | H366: SIMPLIFY
A367: I_MEQ.ERROR.03 | B367: I_MEQ.ERROR | C367: Inventory | D367: Report/print | E367: PRODUCT | F367: ERROR file entries are purged when the date in the 4th '.'-field of the key + 185 days < today (comment at L5 says 120 days) | G367: L83-94 | H367: QUESTION
A368: LOOKUP.01 | B368: LOOKUP | C368: Inventory | D368: Interactive | E368: PRODUCT | F368: PARTS record: attr 1 = location, attr 2 = description (lens parts) | G368: L12-13 | H368: WAREHOUSE-ONLY
A369: PO.DISC.01 | B369: PO.DISC | C369: Inventory | D369: Batch | E369: PO, PRODUCT, PRICING | F369: IVPO line is open when qty ordered (IVPO attr 7) > total received (sum of IVPO attr 9 subvalues via SUMM) | G369: L28-29 | H369: KEEP
A370: PO.DISC.02 | B370: PO.DISC | C370: Inventory | D370: Batch | E370: PO, PRODUCT, PRICING | F370: Open IVPO line whose PO # is not in IVMST attr 20 is appended to IVMST: PO # -> attr 20, PO cost (IVPO attr 8, cents) -> attr 22 (PO.CST, added 01-09-12) | G370: L37-39,98-102 | H370: KEEP
A371: PO.DISC.03 | B371: PO.DISC | C371: Inventory | D371: Batch | E371: PO, PRODUCT, PRICING | F371: If nothing received yet (IVPO attr 9 blank): IVMST attr 21 = qty ordered, attr 23 = blank; if partially received: attr 21 = blank and attr 23 (backorder) = ordered - received | G371: L100-110 | H371: QUESTION
...

Sheet Programs
A1: Program | B1: Domain | C1: Mode | D1: Lines | E1: Relevance | F1: Rules | G1: Questions | H1: Purpose | I1: Files | J1: Calls | K1: Bugs / oddities
A2: 28200.RPT | B2: Reporting | C2: Report/print | D2: 40 | E2: PRODUCT | F2: =COUNTIF(Rules!$B$2:$B$1568,A2) -> 5 | G2: =COUNTIFS(Rules!$B$2:$B$1568,A2,Rules!$H$2:$H$1568,"QUESTION") -> 2 | H2: Builds a per-member TEMPDATA summary of quantity and amount sold for four hard-coded Olympus products from a date range of TEMPHIST (ARHIST copy). | I2: reads TEMPHIST (opened as ARHIST) · writes TEMPDATA (cleared first) | J2: EXECUTE CLEAR-FILE DATA TEMPDATA; EXECUTE SSELECT TEMPHIST | K2: TEMPDATA is cleared on every date-range loop; line loop hard-capped at 800 and stops at first blank product; reads TEMPHIST not ARHIST despite the variable name; amount units not stated (whatever ARHIST attr 4 holds, likely cents).
A3: ADJ | B3: Members | C3: Utility/maintenance | D3: 9 | F3: =COUNTIF(Rules!$B$2:$B$1568,A3) -> 1 | G3: =COUNTIFS(Rules!$B$2:$B$1568,A3,Rules!$H$2:$H$1568,"QUESTION") -> 1 | H3: Manually decrements a member's STOCK warehouse-profit figure by an operator-entered amount. | I3: reads STOCK · writes STOCK | J3: none | K3: READV without lock then WRITEV (lost-update risk); invalid member silently re-prompts; no numeric check on amount.
A4: ADJ.ARHIST | B4: Products | C4: Utility/maintenance | D4: 25 | E4: PRODUCT, PRICING | F4: =COUNTIF(Rules!$B$2:$B$1568,A4) -> 3 | G4: =COUNTIFS(Rules!$B$2:$B$1568,A4,Rules!$H$2:$H$1568,"QUESTION") -> 2 | H4: One-off fix-up that recalculates the cost field (attr 15) on ARHIST lines for returns using IVMST average received cost. | I4: reads ARHIST, IVMST · writes ARHIST | J4: none (relies on an active select list) | K4: Header says "for returns" but nothing filters returns (depends on whatever list is active); MATREADU ELSE GO 5 conflates not-found and locked; RAW "Y" suffix convention is undocumented; mixed money units between branches.
A5: AP.SEL.INVSPC | B5: AP | C5: Interactive | D5: 126 | E5: VENDOR, PRICING | F5: =COUNTIF(Rules!$B$2:$B$1568,A5) -> 11 | G5: =COUNTIFS(Rules!$B$2:$B$1568,A5,Rules!$H$2:$H$1568,"QUESTION") -> 2 | H5: Selects all unpaid AP invoices for one vendor for payment while taking an extra "special" discount off each invoice. | I5: reads APDIST, APHIST, APDUE, APMST, CONTROL · writes APDIST, APHIST, APDUE, CONTROL (APCHK) | J5: CALL IDATE | K5: Held credits left in the list at end of run are never written (lost); held items use APHIST key FIELD(id,'*',1,2) while main path uses full ID — inconsistent keys; error prefix says "AP9"; MATREADU ELSE treats locked as not-found.
A6: AP10 | B6: AP | C6: Interactive | D6: 38 | E6: VENDOR | F6: =COUNTIF(Rules!$B$2:$B$1568,A6) -> 4 | G6: =COUNTIFS(Rules!$B$2:$B$1568,A6,Rules!$H$2:$H$1568,"QUESTION") -> 1 | H6: Cancels the entire pending AP payment selection and reverses special discounts. | I6: reads CONTROL, APDUE, APDIST, APHIST · writes APDIST, APHIST, CONTROL; deletes APDUE | J6: none | K6: Any read failure CHAINs to ABORT mid-run leaving a partially reversed selection; reverses using APHIST key = APDUE ID whereas AP.SEL.INVSPC held-credit path wrote APHIST under FIELD(id,'*',1,2).
A7: AR.ADJ.CY | B7: AR | C7: Utility/maintenance | D7: 18 | F7: =COUNTIF(Rules!$B$2:$B$1568,A7) -> 2 | G7: =COUNTIFS(Rules!$B$2:$B$1568,A7,Rules!$H$2:$H$1568,"QUESTION") -> 2 | H7: Year-roll/reset style fix-up that sets every member's current-year high credit to the current balance. | I7: reads ARMST · writes ARMST | J7: UPD.ARLOG (commented out) | K7: ARLOG audit call commented out despite the 07-23-09 note adding it; units differ between fields (cents vs dollars); MATREADU ELSE silently skips locked records.
A8: AR.CHANGE | B8: AR | C8: Utility/maintenance | D8: 10 | F8: =COUNTIF(Rules!$B$2:$B$1568,A8) -> 2 | G8: =COUNTIFS(Rules!$B$2:$B$1568,A8,Rules!$H$2:$H$1568,"QUESTION") -> 1 | H8: One-off script that re-keys selected ARHIST records to member 2829 (moves history from one member to another). | I8: reads ARHIST · writes ARHIST (write new, delete old) | J8: none (needs active select list) | K8: Silent overwrite of existing history under target key; READU ELSE conflates locked/missing.
A9: AR.INP.DEPTICK | B9: AR | C9: Interactive | D9: 433 | F9: =COUNTIF(Rules!$B$2:$B$1568,A9) -> 10 | G9: =COUNTIFS(Rules!$B$2:$B$1568,A9,Rules!$H$2:$H$1568,"QUESTION") -> 3 | H9: Enters and edits cash deposit tickets (member account, check number, check amount per line) that payments are later applied against. | I9: reads ARMST, DEPTICK, CONTROL, SCREENS · writes DEPTICK, CONTROL ('DEPTICK' counter) | J9: RAWINPUT, IDATE, MONEY, SUMM; INCLUDE FILE.INCLUDES ARMST.FIELDS, DEPTICK.FIELDS (include files not in extract) | K9: Existing ticket lock is released immediately after read (L89) and edits are written later without a lock — concurrent payment posting (AR.INP.PAYMNTS) can be overwritten; line delete is allowed even after payments were applied to that check; ticket counter can exceed 3 digits and break the 5-digit ID format.
A10: AR.INP.PAYMNTS | B10: AR | C10: Interactive | D10: 1137 | E10: VENDOR | F10: =COUNTIF(Rules!$B$2:$B$1568,A10) -> 33 | G10: =COUNTIFS(Rules!$B$2:$B$1568,A10,Rules!$H$2:$H$1568,"QUESTION") -> 9 | H10: Applies deposit-ticket checks to member open invoices (pay due, pay all, by invoice), with discounts, partial payments, adjustments and vendor credit memos that also post AP credits. | I10: reads APMST, APDIST, APHIST, ARMST, ARINV, DEPTICK, CONTROL ('UPD','APBAT','APPER','MS'), SCREENS · writes ARMST, ARINV, DEPTICK, APDIST, APHIST, APMST, CONTROL | J10: RAWINPUT, MONEY, SUMM, DSP.REPORT, SUBR('-NES'); EXECUTE TERM, SORT DEPTICK; INCLUDE *.FIELDS (not in extract) | K10: Auto-apply (L203-207) pays each invoice's full due even when it exceeds the remaining check (overpay guard commented out); period error message ("2 prior or 1 future") contradicts code (1 prior, up to 2 future); PAYOPT=0 test unreachable; UPD.APDIST sets ERR not EM so a missing-vendor message never shows, then MATWRITEs a blank APMST record; READ.DEPTICK retry loop exits after one wait so DEPTICK may silently not update after ARMST/ARINV were written; MATREADU ARINV ELSE proceeds with empty record (conflates not found/locked); APHIST NET sign opposite to GROSS; YTD.DISC adds 0.
A11: AR.INQ.DEPTICK | B11: AR | C11: Subroutine | D11: 107 | F11: =COUNTIF(Rules!$B$2:$B$1568,A11) -> 2 | G11: =COUNTIFS(Rules!$B$2:$B$1568,A11,Rules!$H$2:$H$1568,"QUESTION") -> 0 | H11: POSH screen-framework hook for the deposit ticket inquiry screen (inquiry only, optional print). | I11: none directly (screen framework via POSH includes; would LIST ARDEPTIC) · writes none | J11: none (EXECUTE of LIST ARDEPTIC is commented out) | K11: Print path is dead; uses a different file name (ARDEPTIC) from the BASIC programs (DEPTICK).
A12: AR.PRT.CRDMEM | B12: AR | C12: Report/print | D12: 167 | E12: VENDOR | F12: =COUNTIF(Rules!$B$2:$B$1568,A12) -> 3 | G12: =COUNTIFS(Rules!$B$2:$B$1568,A12,Rules!$H$2:$H$1568,"QUESTION") -> 0 | H12: Lists member credit memos (ARINV code "CM" splits) for a date range, by member or by vendor, with subtotals. | I12: reads ARMST, APMST, ARINV, CONTROL · writes none | J12: IDATE, P.ASSIGN.SUB, DSP.REPORT; EXECUTE SSELECT ARINV | K12: Only the first CM subvalue per invoice is reported (one CM per invoice is enforced in AR.INP.PAYMNTS); L136 ELSE sets NAME not MNAME so a missing member shows the previous member's name; OPT=1 sorts BY-EXP CODE, not by member.
A13: AR.PRT.EDIINV | B13: AR | C13: Report/print | D13: 83 | E13: VENDOR, PRICING | F13: =COUNTIF(Rules!$B$2:$B$1568,A13) -> 5 | G13: =COUNTIFS(Rules!$B$2:$B$1568,A13,Rules!$H$2:$H$1568,"QUESTION") -> 2 | H13: Prints "Billing for <vendor>" invoices to members for vendor-billed (EDI) shipments held in ARSHIP, using the vendor's own product/description/qty/cost lines. | I13: reads ARSHIP, ARMST, IVMST (opened, unused), CONTROL ('COPY'), APMST · writes none | J13: EXECUTE SSELECT ARSHIP | K13: Prints every ARSHIP record (no selection criteria); IVMST opened but unused; the "3-digit decimals" comment conflicts with dividing cents by 100 (units of VCOST unclear); fixed-form printer escape codes.
A14: AR.RPT.DEPTICK | B14: AR | C14: Report/print | D14: 46 | F14: =COUNTIF(Rules!$B$2:$B$1568,A14) -> 1 | G14: =COUNTIFS(Rules!$B$2:$B$1568,A14,Rules!$H$2:$H$1568,"QUESTION") -> 0 | H14: Detail or summary report of deposit tickets in a ticket-number range (amounts, unapplied, discount adj, CM, adjustments). | I14: reads DEPTICK · writes none | J14: DSP.REPORT; EXECUTE SORT DEPTICK | K14: Ticket IDs are MM+seq so a numeric range spans months oddly; DISC.ADJ dictionary item not in the extracted DEPTICK dict.
A15: AR.SHIP.MNT | B15: Members | C15: Interactive | D15: 436 | F15: =COUNTIF(Rules!$B$2:$B$1568,A15) -> 11 | G15: =COUNTIFS(Rules!$B$2:$B$1568,A15,Rules!$H$2:$H$1568,"QUESTION") -> 2 | H15: Maintains a member's alternate ship-to addresses (SHIPTO records keyed member*code) with UPS zone derived from ZIP. | I15: reads ARMST, SHIPTO, ZIPREF ('UPS', 'STATES', zip records) · writes SHIPTO (write/delete) | J15: EDIT.LINE; EXECUTE SSELECT SHIPTO; INCLUDE ARMST/SHIPTO/ZIPREF.FIELDS (not in extract) | K15: SHIP.ZONE is unreachable (not in the 1-6 correction menu nor the new-entry flow), so manual zone override never runs; L277 deletes ADDRS1 (typo for ADDR1S); L330 missing ";" between ADDR1S and ADDR2S assignments; header says ship-to "later to be added to ARMST" while ARMST already has SHIP.STREET/SHIP.CSZ (attrs 31-32).
A16: AR.TEST.SUB | B16: AR | C16: Utility/maintenance | D16: 38 | F16: =COUNTIF(Rules!$B$2:$B$1568,A16) -> 1 | G16: =COUNTIFS(Rules!$B$2:$B$1568,A16,Rules!$H$2:$H$1568,"QUESTION") -> 0 | H16: One-off diagnostic (GJS 12-27-1999) counting ARINV records that have multiple partial payments. | I16: reads ARINV · writes none | J16: EXECUTE SELECT ARINV | K16: Diagnostic only; no business effect.
A17: AR.UPD.PRO.SUB | B17: AR | C17: Subroutine | D17: 793 | E17: VENDOR | F17: =COUNTIF(Rules!$B$2:$B$1568,A17) -> 13 | G17: =COUNTIFS(Rules!$B$2:$B$1568,A17,Rules!$H$2:$H$1568,"QUESTION") -> 3 | H17: POSH-framework payment-posting screen (called from AR.UPD.DEPTICK) that applies one check to a member's open invoices with full/skip/partial/non-cash codes and writes ARINV/ARMST; an earlier (1999) alternative to AR.INP.PAYMNTS. | I17: reads POSH.WORK ('AR.UPD.PRO.SUB*'port), ARINV, ARMST, APMST · writes ARINV, ARMST, POSH.WORK | J17: POSH.ERROR, POSH.INPUT, MONEY; EXECUTE WHO | K17: Looks unfinished — debug prompt "AT BUILD REC TO WRITE" + INPUT before posting (L685-686); skip test at L339 is always true (NE "" OR NE 2); WORKREC is indexed by display position while posting LOCATEs by invoice number; full-pay reduces balance by the invoice gross although cash = net; MATREADU ELSE STOP conflation is handled with LOCKED clause (ok); DIM AR.MST(34) smaller than ARMST record (47 attrs).
A18: AR1 | B18: Members | C18: Interactive | D18: 124 | F18: =COUNTIF(Rules!$B$2:$B$1568,A18) -> 11 | G18: =COUNTIFS(Rules!$B$2:$B$1568,A18,Rules!$H$2:$H$1568,"QUESTION") -> 5 | H18: Adds new members (auto-numbered) or changes existing member master data (name, address, credit limit, phone, mailings, dues, EIN). | I18: reads CONTROL ('AR'), ARMST, ZIPREF ('UPS','STATES'), STOCK · writes ARMST, STOCK, CONTROL | J18: none | K18: US-only ZIP (AR.SHIP.MNT later allowed Canadian); no lock on CONTROL 'AR' (READV/WRITEV) → duplicate numbers possible; ZIP lookup with Z=0 when prefix below first entry gives empty zone.
A19: AR10 | B19: AR | C19: Batch | D19: 28 | F19: =COUNTIF(Rules!$B$2:$B$1568,A19) -> 3 | G19: =COUNTIFS(Rules!$B$2:$B$1568,A19,Rules!$H$2:$H$1568,"QUESTION") -> 0 | H19: After invoice printing, copies ARSHIP to ARHIST, clears ARSHIP, and deletes billed SCANORD records. | I19: reads ARSHIP, SCANORD · writes ARHIST; clears ARSHIP; deletes SCANORD | J19: EXECUTE COPY FROM ARSHIP TO ARHIST ALL; EXECUTE SELECT SCANORD WITH BILL.DATE | K19: COPY without OVERWRITING silently skips keys already in ARHIST, then ARSHIP is cleared anyway — potential history loss; no check that the copy succeeded.
A20: AR11 | B20: AR | C20: Utility/maintenance | D20: 26 | F20: =COUNTIF(Rules!$B$2:$B$1568,A20) -> 1 | G20: =COUNTIFS(Rules!$B$2:$B$1568,A20,Rules!$H$2:$H$1568,"QUESTION") -> 0 | H20: Recomputes ARMST aging buckets and balance from ARINV open invoices (marked "DON'T USE"). | I20: reads ARINV, ARMST · writes ARMST | J20: none | K20: Header "$$%% DON'T USE" (L2 is not valid BASIC); 300-invoice cap; no locks.
A21: AR12 | B21: AR | C21: Batch | D21: 67 | E21: VENDOR, PRODUCT | F21: =COUNTIF(Rules!$B$2:$B$1568,A21) -> 6 | G21: =COUNTIFS(Rules!$B$2:$B$1568,A21,Rules!$H$2:$H$1568,"QUESTION") -> 2 | H21: Year-end roll: moves YTD figures to prior year and zeroes YTD counters on STOCK, IVMST, VNMST, ARMST; clears IVSOLD and IVEND. | I21: reads STOCK, IVMST, VNMST, ARMST · writes STOCK, IVMST, VNMST, ARMST; clears IVSOLD, IVEND | J21: none | K21: Prior-year fields stored in dollars while YTD in cents (unit inconsistency); 11-26-01 note says ARMST attr 22 no longer holds shares but share calc removed; AR.ADJ.CY sets HI.CRED from PY.HI.CRED instead — two different year-end rules; MATREADU ELSE skips locked records silently.
A22: AR13 | B22: Members | C22: Report/print | D22: 33 | F22: =COUNTIF(Rules!$B$2:$B$1568,A22) -> 4 | G22: =COUNTIFS(Rules!$B$2:$B$1568,A22,Rules!$H$2:$H$1568,"QUESTION") -> 2 | H22: Prints annual member stock (patronage share) letters (1986). | I22: reads ARMST, STOCK · writes none | J22: none | K22: "19":YEAR Y2K bug; STOCK attr 3 meaning conflicts with dict (PATR.BAL).
A23: AR14 | B23: Members | C23: Utility/maintenance | D23: 18 | F23: =COUNTIF(Rules!$B$2:$B$1568,A23) -> 1 | G23: =COUNTIFS(Rules!$B$2:$B$1568,A23,Rules!$H$2:$H$1568,"QUESTION") -> 1 | H23: Sequentially numbers ARMST/ARMST2 field 28, 29, 33, 34 or 35 from an active select list. | I23: reads (select list) · writes operator-named file (ARMST or ARMST2) | J23: none | K23: Prompt lists 28/29/33/34 but also accepts 35 (PROMASTER) — would overwrite PROMASTER flag with a sequence number.
A24: AR15 | B24: Members | C24: Utility/maintenance | D24: 13 | F24: =COUNTIF(Rules!$B$2:$B$1568,A24) -> 1 | G24: =COUNTIFS(Rules!$B$2:$B$1568,A24,Rules!$H$2:$H$1568,"QUESTION") -> 1 | H24: Calculator for member share buyout to cap holdings at a percentage of total shares. | I24: none | J24: none | K24: Must edit code to change the percentage; header says 5% but live code uses 20%.
A25: AR16 | B25: Members | C25: Interactive | D25: 34 | F25: =COUNTIF(Rules!$B$2:$B$1568,A25) -> 2 | G25: =COUNTIFS(Rules!$B$2:$B$1568,A25,Rules!$H$2:$H$1568,"QUESTION") -> 1 | H25: Toggles a member's credit-hold status. | I25: reads ARMST · writes ARMST | J25: none | K25: Mixed money units on one screen; no audit of who placed the hold.
A26: AR17 | B26: Vendors | C26: Utility/maintenance | D26: 27 | E26: VENDOR | F26: =COUNTIF(Rules!$B$2:$B$1568,A26) -> 1 | G26: =COUNTIFS(Rules!$B$2:$B$1568,A26,Rules!$H$2:$H$1568,"QUESTION") -> 1 | H26: Fills IVEND attrs 4/5 with each member's combined amount and surcharge for vendors 195 and 279. | I26: reads IVEND · writes IVEND | J26: none | K26: LOCATE BY 'AR' assumes IVEND attr 1 vendor list sorted; unlocked MATREAD then MATWRITE; OPEN failure doesn't stop.
A27: AR18 | B27: Members | C27: Interactive | D27: 55 | E27: VENDOR | F27: =COUNTIF(Rules!$B$2:$B$1568,A27) -> 4 | G27: =COUNTIFS(Rules!$B$2:$B$1568,A27,Rules!$H$2:$H$1568,"QUESTION") -> 1 | H27: Credits members with extra surcharge income and gross purchases from direct-billing vendors (manual entry per vendor/member). | I27: reads APMST, ARMST, BVEND · writes ARMST, BVEND | J27: none | K27: Cents-without-decimal entry differs from programs using MONEY; no audit trail of who entered what.
A28: AR19 | B28: Members | C28: Interactive | D28: 128 | E28: VENDOR, PO | F28: =COUNTIF(Rules!$B$2:$B$1568,A28) -> 6 | G28: =COUNTIFS(Rules!$B$2:$B$1568,A28,Rules!$H$2:$H$1568,"QUESTION") -> 0 | H28: Enters/edits member open direct-vendor POs (VENDORD) that count against the member's credit exposure. | I28: reads ARMST, APMST, VENDORD · writes VENDORD | J28: MONEY | K28: A "change" reached via the L44-54 loop keeps ADD=1 and inserts a duplicate instead of updating; YN can be stale in that loop; BILLED (attr 5) is never set here.
A29: AR1A | B29: Members | C29: Interactive | D29: 120 | F29: =COUNTIF(Rules!$B$2:$B$1568,A29) -> 4 | G29: =COUNTIFS(Rules!$B$2:$B$1568,A29,Rules!$H$2:$H$1568,"QUESTION") -> 2 | H29: Copy of AR1 for adding/changing IPI (non-PRO) members; only differences listed. | I29: reads CONTROL ('AR2'), ARMST, ZIPREF · writes ARMST, CONTROL | J29: none | K29: Duplicates AR1 logic; "IPI" not defined anywhere in code; attr 23 overloaded (mailings prompt vs member type).
A30: AR1B | B30: Members | C30: Interactive | D30: 137 | F30: =COUNTIF(Rules!$B$2:$B$1568,A30) -> 6 | G30: =COUNTIFS(Rules!$B$2:$B$1568,A30,Rules!$H$2:$H$1568,"QUESTION") -> 3 | H30: Copy of AR1A (05-26-11) for adding/changing Canadian affiliate members; only differences listed. | I30: reads CONTROL ('AR2'), ARMST, ZIPREF ('PROVINCE') · writes ARMST, CONTROL | J30: none | K30: Message says "PRO or AFF" for type 2 while AR1A calls type 2 IPI — naming of member types inconsistent.
A31: AR2 | B31: AR | C31: Report/print | D31: 71 | E31: VENDOR, PRICING | F31: =COUNTIF(Rules!$B$2:$B$1568,A31) -> 5 | G31: =COUNTIFS(Rules!$B$2:$B$1568,A31,Rules!$H$2:$H$1568,"QUESTION") -> 1 | H31: Prints member invoices from ARSHIP (1994 version): PRO product lines, or a single "Billing for <vendor>" line for direct-bill vendor charges with a terms-dispute notice. | I31: reads ARSHIP, ARMST, IVMST, CONTROL ('COPY'), APMST · writes none | J31: none (relies on active select list) | K31: 200-line cap; unit price derived by division (may round); superseded in part by AR.PRT.EDIINV and AR5 variants.
A32: AR20 | B32: Members | C32: Interactive | D32: 36 | F32: =COUNTIF(Rules!$B$2:$B$1568,A32) -> 2 | G32: =COUNTIFS(Rules!$B$2:$B$1568,A32,Rules!$H$2:$H$1568,"QUESTION") -> 1 | H32: Adds/changes a member's permanent ship-to address on ARMST and resets the UPS zone from the ship-to ZIP. | I32: reads ARMST, ZIPREF ('UPS','STATES') · writes ARMST | J32: none | K32: Zone overwrite drops the air-zone suffix that AR1 maintains in attr 25; US ZIP only; LOCATE 'AL' assumes STATES sorted while AR1 uses unsorted LOCATE.
A33: AR21 | B33: Members | C33: Utility/maintenance | D33: 17 | E33: VENDOR | F33: =COUNTIF(Rules!$B$2:$B$1568,A33) -> 1 | G33: =COUNTIFS(Rules!$B$2:$B$1568,A33,Rules!$H$2:$H$1568,"QUESTION") -> 0 | H33: One-off 1995 conversion setting ARMST prior-year sales from old ARMST2 YTD plus BVEND2 direct-bill amounts. | I33: reads ARMST2, BVEND2 · writes ARMST | J33: none | K33: Second term is not truncated to whole dollars (fractional dollars added to a whole-dollar field); READVU lock then WRITEV.
A34: AR3 | B34: AR | C34: Interactive | D34: 285 | F34: =COUNTIF(Rules!$B$2:$B$1568,A34) -> 16 | G34: =COUNTIFS(Rules!$B$2:$B$1568,A34,Rules!$H$2:$H$1568,"QUESTION") -> 6 | H34: Original member payment entry (no deposit ticket): pays due/all/selected invoices with prompt-pay discount, records credits, updates ARMST/ARINV and stamps date paid on ARHIST. | I34: reads ARMST, ARINV, ARHIST, CONTROL ('UPD','INV','MS') · writes ARMST, ARINV, ARHIST (attr 16), CONTROL ('INV','MS') | J34: MONEY; UPD.ARLOG (commented out); EXECUTE SELECT ARHIST | K34: LOCKED clauses at L243 and L260 set NOT.LOCKED = 1, so lock waits never happen; credit path (L251-254) calls the payment routine with stale B() values from the last invoice viewed; credit invoice written with no amount (attr 3) — only AMTPAID; open-error label for ARHIST says ARMST; ARLOG audit commented out; discount rules differ between options.
A35: AR4 | B35: AR | C35: Batch | D35: 76 | E35: PRODUCT | F35: =COUNTIF(Rules!$B$2:$B$1568,A35) -> 8 | G35: =COUNTIFS(Rules!$B$2:$B$1568,A35,Rules!$H$2:$H$1568,"QUESTION") -> 2 | H35: Month-end AR close: purges fully paid invoices, ages open invoices, assesses 1.5% service charges, rolls ARMST aging buckets and advances the AR month. | I35: reads CONTROL ('UPD'), ARMST, ARINV, DICT IVMST (opened, write commented out) · writes ARMST, ARINV, ARSHIP, CONTROL | J35: none | K35: Header says service charge "at 30, not 60 days" but CURRENT is included in the base; SID "date − 9000 to retain 4 digits" now yields 5 digits (dates > 19000) and can collide across years; if ARINV is missing the ARMST lock is released then the record is still written; DICT IVMST opened but unused; fractions dropped by INT not rounded.
A36: AR5 | B36: AR | C36: Report/print | D36: 107 | F36: =COUNTIF(Rules!$B$2:$B$1568,A36) -> 7 | G36: =COUNTIFS(Rules!$B$2:$B$1568,A36,Rules!$H$2:$H$1568,"QUESTION") -> 0 | H36: Prints monthly member statements (three-part pre-printed form) with prompt-pay discount and past-due flags, and advances the month-end state. | I36: reads CONTROL ('UPD'), ARINV, ARMST · writes ERROR (missing records), CONTROL ('UPD' attr 1 = 4) | J36: none (relies on active select list) | K36: Missing ARINV/ARMST are logged to ERROR and the run ABORTs at end; READVU on 'UPD' held for whole run; discount column shows terms % even when past due.
A37: AR5.LASER | B37: AR | C37: Test-variant | D37: 151 | E37: VENDOR | F37: =COUNTIF(Rules!$B$2:$B$1568,A37) -> 3 | G37: =COUNTIFS(Rules!$B$2:$B$1568,A37,Rules!$H$2:$H$1568,"QUESTION") -> 0 | H37: Laser-printer (PCL) version of AR5 statements that also shows the vendor invoice number and vendor name per line; only differences from AR5 listed. | I37: reads APMST, ARMST, ARINV, ARHIST, ARHIST.98, CONTROL · writes ERROR, CONTROL | J37: none | K37: Hard-coded archive file name ARHIST.98 (1998 history) — later years' archived invoices not found; PCL escape strings hard-coded.
A38: AR5.LASER.INTERIM | B38: AR | C38: Test-variant | D38: 152 | E38: VENDOR | F38: =COUNTIF(Rules!$B$2:$B$1568,A38) -> 3 | G38: =COUNTIFS(Rules!$B$2:$B$1568,A38,Rules!$H$2:$H$1568,"QUESTION") -> 2 | H38: Mid-month ("interim") variant of AR5.LASER; only differences listed. | I38: reads APMST, ARMST, ARINV, ARHIST, ARHIST.00, CONTROL · writes ERROR, CONTROL | J38: none | K38: Still writes CONTROL 'UPD' = 4 when UPD = 3 even though it is an interim run (inherited L-149 logic); hard-coded archive year.
A39: AR5.OFFICE | B39: AR | C39: Test-variant | D39: 154 | F39: =COUNTIF(Rules!$B$2:$B$1568,A39) -> 1 | G39: =COUNTIFS(Rules!$B$2:$B$1568,A39,Rules!$H$2:$H$1568,"QUESTION") -> 0 | H39: Office-copy variant of AR5.LASER; only differences listed. | I39: reads APMST, ARMST, ARINV, ARHIST, ARHIST.98, CONTROL · writes ERROR, CONTROL | J39: none | K39: Reads ARHIST/APMST per line for nothing; same UPD=4 side effect as AR5.
A40: AR6 | B40: Reporting | C40: Utility/maintenance | D40: 21 | E40: VENDOR | F40: =COUNTIF(Rules!$B$2:$B$1568,A40) -> 1 | G40: =COUNTIFS(Rules!$B$2:$B$1568,A40,Rules!$H$2:$H$1568,"QUESTION") -> 0 | H40: Rescales the ARMST "GRAPH" dictionary item (member sales bar graph) to the current largest member's sales. | I40: reads ARMST, BVEND · writes DICT ARMST 'GRAPH' | J40: EXECUTE CD ARMST GRAPH | K40: Program rewrites a dictionary at runtime; aborts if any ARMST lacks attr 9.
...
